<?xml version="1.0" ?>
<robot name="ros_dd_small">
    <gazebo>
        <plugin name="differential_drive_controller" filename="libgazebo_ros_diff_drive.so">
            <legacyMode>false</legacyMode>
            
            <left_joint>wheel1_joint</left_joint> 
            <right_joint>wheel2_joint</right_joint> 
            
            <wheel_separation>0.35</wheel_separation>
             <wheel_diameter>0.15</wheel_diameter> 
            
            <command_topic>cmd_vel</command_topic>
            <odometry_topic>odom</odometry_topic>
            <odometry_frame>odom</odometry_frame>
            <robot_base_frame>body_link</robot_base_frame>
            <publish_odom>true</publish_odom>
            <publish_odom_tf>true</publish_odom_tf>
            
            <max_wheel_torque>200</max_wheel_torque>
            <max_wheel_acceleration>10.0</max_wheel_acceleration>
        </plugin>
    </gazebo>

    <link name="body_link">
        <visual>
            <origin rpy="0 0 0" xyz="0 0 0"/>
            <geometry>
                <box size="0.5 0.3 0.15"/>
            </geometry>
            <material name="red">
                <color rgba="1 0 0 1"/>
            </material>
        </visual>
        
        <collision>
            <origin rpy="0 0 0" xyz="0 0 0"/>
            <geometry>
                <box size="0.5 0.3 0.15"/>
            </geometry>
        </collision>
        
        <inertial>
            <mass value="1.25"/>
            <origin xyz="0 0 0"/>
            <inertia ixx="0.030" ixy="0.0" ixz="0.0" 
                     iyy="0.030" iyz="0.0" 
                     izz="0.030"/>
        </inertial>

        <gazebo>
            <plugin name="imu_plugin" filename="libgazebo_ros_imu.so">
                <alwaysOn>true</alwaysOn>
                <updateRate>100.0</updateRate>
                <bodyName>body_link</bodyName>
                <topicName>imu/data</topicName>
                <gaussianNoise>0.005</gaussianNoise>
                <xyzOffset>0 0 0</xyzOffset> <rpyOffset>0 0 0</rpyOffset>
            </plugin>
        </gazebo>
    </link>
    
    <joint name="laser_joint" type="fixed">
        <origin xyz="0.225 0 0.125" rpy="0 0 0"/>
        <parent link="body_link"/>
        <child link="laser_link"/>
    </joint>
    
    <link name="laser_link">
        <visual>
            <origin rpy="0 0 0" xyz="0 0 0"/>
            <geometry>
                <cylinder length="0.05" radius="0.025"/>
            </geometry>
            <material name="black">
                <color rgba="1 0 0 1"/>
            </material>
        </visual>
        
        <collision>
            <origin rpy="0 0 0" xyz="0 0 0"/>
            <geometry>
                <cylinder length="0.05" radius="0.025"/>
            </geometry>
        </collision>
        <inertial>
            <mass value="0.0125"/>
            <origin xyz="0 0 0"/>
            <inertia ixx="0.000006" ixy="0.0" ixz="0.0" iyy="0.000006" iyz="0.0" izz="0.000003"/>
        </inertial>
        
        <gazebo reference="laser_link">
            <sensor type="ray" name="laser_sensor">
                <pose>0 0 0 0 0 0</pose>
                <visualize>true</visualize>
                <update_rate>10</update_rate>
                <ray>
                    <scan>
                        <horizontal>
                            <samples>720</samples>
                            <resolution>1</resolution>
                            <min_angle>-2.356194</min_angle> <max_angle>2.356194</max_angle> 
                        </horizontal>
                    </scan>
                    <range>
                        <min>0.10</min>
                        <max>10.0</max>
                        <resolution>0.01</resolution>
                    </range>
                    <noise>
                        <type>gaussian</type>
                        <mean>0.0</mean>
                        <stddev>0.01</stddev>
                    </noise>
                </ray>
                <plugin name="gazebo_ros_laser_controller" filename="libgazebo_ros_ray_sensor.so">
                    <ros>
                        <argument>~/out:=scan</argument>
                        <namespace>/</namespace>
                    </ros>
                    <output_type>sensor_msgs/LaserScan</output_type>
                    <frame_name>laser_link</frame_name>
                </plugin>
            </sensor>
        </gazebo>
    </link>

    <joint name="wheel1_joint" type="continuous">
        <parent link="body_link"/>
        <child link="wheel1_link" />
        <origin xyz="-0.15 -0.175 -0.05" rpy="0 0 0"/>
        <axis xyz="0 1 0" />
    </joint>
    <link name="wheel1_link">
        <visual>
            <origin rpy="1.570795 0 0" xyz="0 0 0"/>
            <geometry>
                <cylinder length="0.05" radius="0.075"/>
            </geometry>
            <material name="yellow">
                <color rgba="1 1 0 1"/>
            </material>
        </visual>
        <collision>
            <origin rpy="1.570795 0 0" xyz="0 0 0"/>
            <geometry>
                <cylinder length="0.05" radius="0.075"/>
            </geometry>
        </collision>
        <inertial>
            <mass value="0.0625"/>
            <origin rpy="1.570795 0 0" xyz="0 0 0"/>
            <inertia ixx="0.00009" ixy="0.0" ixz="0.0" iyy="0.00009" iyz="0.0" izz="0.00009"/>
        </inertial>
    </link>

    <joint name="wheel2_joint" type="continuous">
        <parent link="body_link"/>
        <child link="wheel2_link" />
        <origin xyz="-0.15 0.175 -0.05" rpy="0 0 0"/>
        <axis xyz="0 1 0" />
    </joint>
    <link name="wheel2_link">
        <visual>
            <origin rpy="1.570795 0 0" xyz="0 0 0"/>
            <geometry>
                <cylinder length="0.05" radius="0.075"/>
            </geometry>
            <material name="yellow">
                <color rgba="1 1 0 1"/>
            </material>
        </visual>
        <collision>
            <origin rpy="1.570795 0 0" xyz="0 0 0"/>
            <geometry>
                <cylinder length="0.05" radius="0.075"/>
            </geometry>
        </collision>
        <inertial>
            <mass value="0.0625"/>
            <origin rpy="1.570795 0 0" xyz="0 0 0"/>
            <inertia ixx="0.00009" ixy="0.0" ixz="0.0" iyy="0.00009" iyz="0.0" izz="0.00009"/>
        </inertial>
    </link>

    <joint name="wheel3_joint" type="continuous">
        <parent link="body_link"/>
        <child link="wheel3_link" />
        <origin xyz="0.15 -0.175 -0.05" rpy="0 0 0"/>
        <axis xyz="0 1 0" />
    </joint>
    <link name="wheel3_link">
        <visual>
            <origin rpy="1.570795 0 0" xyz="0 0 0"/>
            <geometry>
                <cylinder length="0.05" radius="0.075"/>
            </geometry>
            <material name="yellow">
                <color rgba="1 1 0 1"/>
            </material>
        </visual>
        <collision>
            <origin rpy="1.570795 0 0" xyz="0 0 0"/>
            <geometry>
                <cylinder length="0.05" radius="0.075"/>
            </geometry>
        </collision>
        <inertial>
            <mass value="0.0625"/>
            <origin rpy="1.570795 0 0" xyz="0 0 0"/>
            <inertia ixx="0.00009" ixy="0.0" ixz="0.0" iyy="0.00009" iyz="0.0" izz="0.00009"/>
        </inertial>
    </link>

    <joint name="wheel4_joint" type="continuous">
        <parent link="body_link"/>
        <child link="wheel4_link" />
        <origin xyz="0.15 0.175 -0.05" rpy="0 0 0"/>
        <axis xyz="0 1 0" />
    </joint>
    <link name="wheel4_link">
        <visual>
            <origin rpy="1.570795 0 0" xyz="0 0 0"/>
            <geometry>
                <cylinder length="0.05" radius="0.075"/>
            </geometry>
            <material name="yellow">
                <color rgba="1 1 0 1"/>
            </material>
        </visual>
        <collision>
            <origin rpy="1.570795 0 0" xyz="0 0 0"/>
            <geometry>
                <cylinder length="0.05" radius="0.075"/>
            </geometry>
        </collision>
        <inertial>
            <mass value="0.0625"/>
            <origin rpy="1.570795 0 0" xyz="0 0 0"/>
            <inertia ixx="0.00009" ixy="0.0" ixz="0.0" iyy="0.00009" iyz="0.0" izz="0.00009"/>
        </inertial>
    </link>

</robot>