<?xml version="1.0" ?>
<sdf version='1.5'>
  <model name='ros_dd_world_scaled_1_2_stabilized'>
    <link name='body_link'>
      <inertial>
        <pose>0 0 0 0 -0 0</pose>
        <mass>5</mass>
        <inertia>
          <ixx>0.046875</ixx>
          <ixy>0</ixy>
          <ixz>0</ixz>
          <iyy>0.1135415</iyy>
          <iyz>0</iyz>
          <izz>0.1416665</izz>
        </inertia>
      </inertial>
      <collision name='body_link_collision'>
        <pose>0 0 0 0 -0 0</pose>
        <geometry>
          <box>
            <size>0.5 0.3 0.15</size>
          </box>
        </geometry>
      </collision>
      <visual name='body_link_visual'>
        <pose>0 0 0 0 -0 0</pose>
        <geometry>
          <box>
            <size>0.5 0.3 0.15</size>
          </box>
        </geometry>
      </visual>
    </link>
    
    <joint name='wheel1_joint' type='revolute'>
      <pose relative_to='body_link'>-0.15 -0.175 -0.05 0 -0 0</pose>
      <parent>body_link</parent>
      <child>wheel1_link</child>
      <axis>
        <xyz>0 1 0</xyz>
        <limit>
          <lower>-1e+16</lower>
          <upper>1e+16</upper>
        </limit>
        <dynamics>
          <spring_reference>0</spring_reference>
          <spring_stiffness>0</spring_stiffness>
        </dynamics>
      </axis>
    </joint>
    <link name='wheel1_link'>
      <pose relative_to='wheel1_joint'>0 0 0 0 -0 0</pose>
      <inertial>
        <pose>0 0 0 0 -0 0</pose>
        <mass>0.5</mass>
        <inertia>
          <ixx>0.00096875</ixx>
          <ixy>0</ixy>
          <ixz>0</ixz>
          <iyy>0.00096875</iyy>
          <iyz>0</iyz>
          <izz>0.00140625</izz>
        </inertia>
      </inertial>
      <collision name='wheel1_link_collision'>
        <pose>0 0 0 1.57079 -0 0</pose>
        <geometry>
          <cylinder>
            <length>0.05</length>
            <radius>0.075</radius>
          </cylinder>
        </geometry>
      </collision>
      <visual name='wheel1_link_visual'>
        <pose>0 0 0 1.57079 -0 0</pose>
        <geometry>
          <cylinder>
            <length>0.05</length>
            <radius>0.075</radius>
          </cylinder>
        </geometry>
      </visual>
    </link>
    
    <joint name='wheel2_joint' type='revolute'>
      <pose relative_to='body_link'>-0.15 0.175 -0.05 0 -0 0</pose>
      <parent>body_link</parent>
      <child>wheel2_link</child>
      <axis>
        <xyz>0 1 0</xyz>
        <limit>
          <lower>-1e+16</lower>
          <upper>1e+16</upper>
        </limit>
        <dynamics>
          <spring_reference>0</spring_reference>
          <spring_stiffness>0</spring_stiffness>
        </dynamics>
      </axis>
    </joint>
    <link name='wheel2_link'>
      <pose relative_to='wheel2_joint'>0 0 0 0 -0 0</pose>
      <inertial>
        <pose>0 0 0 0 -0 0</pose>
        <mass>0.5</mass>
        <inertia>
          <ixx>0.00096875</ixx>
          <ixy>0</ixy>
          <ixz>0</ixz>
          <iyy>0.00096875</iyy>
          <iyz>0</iyz>
          <izz>0.00140625</izz>
        </inertia>
      </inertial>
      <collision name='wheel2_link_collision'>
        <pose>0 0 0 1.57079 -0 0</pose>
        <geometry>
          <cylinder>
            <length>0.05</length>
            <radius>0.075</radius>
          </cylinder>
        </geometry>
      </collision>
      <visual name='wheel2_link_visual'>
        <pose>0 0 0 1.57079 -0 0</pose>
        <geometry>
          <cylinder>
            <length>0.05</length>
            <radius>0.075</radius>
          </cylinder>
        </geometry>
      </visual>
    </link>
    
    <joint name='caster_joint' type='fixed'>
      <pose relative_to='body_link'>0.2 0 -0.17 0 -0 0</pose>
      <parent>body_link</parent>
      <child>caster_link</child>
    </joint>
    <link name='caster_link'>
      <pose relative_to='caster_joint'>0 0 0 0 -0 0</pose>
      <inertial>
        <pose>0 0 0 0 -0 0</pose>
        <mass>0.08</mass>
        <inertia>
          <ixx>0.000002</ixx>
          <ixy>0</ixy>
          <ixz>0</ixz>
          <iyy>0.000002</iyy>
          <iyz>0</iyz>
          <izz>0.000002</izz>
        </inertia>
      </inertial>
      <collision name='caster_link_collision'>
        <pose>0 0 0 0 -0 0</pose>
        <geometry>
          <sphere>
            <radius>0.025</radius>
          </sphere>
        </geometry>
        <surface>
          <friction>
            <ode>
              <mu>0.0</mu>
              <mu2>0.0</mu2>
            </ode>
          </friction>
        </surface>
      </collision>
      <visual name='caster_link_visual'>
        <pose>0 0 0 0 -0 0</pose>
        <geometry>
          <sphere>
            <radius>0.025</radius>
          </sphere>
        </geometry>
      </visual>
    </link>
    
  </model>
</sdf>